[2024-06-11T21:58:00.867+0000] {task_context_logger.py:104} ERROR - Executor reports task instance <TaskInstance: load_data_mb.load_index_id_703831 manual__2024-06-11T21:47:06.735792+00:00 [queued]> finished (failed) although the task says it's queued. (Info: None) Was the task killed externally?
