[2024-04-25T21:11:25.194+0000] {task_context_logger.py:104} ERROR - Executor reports task instance <TaskInstance: my_dag.task_8 manual__2024-04-25T21:10:20.644441+00:00 [queued]> finished (failed) although the task says it's queued. (Info: None) Was the task killed externally?
