[2024-06-07T00:06:17.316+0000] {local_task_job_runner.py:120} INFO - ::group::Pre task execution logs
[2024-06-07T00:06:17.356+0000] {taskinstance.py:2073} INFO - Dependencies all met for dep_context=non-requeueable deps ti=<TaskInstance: load_data_mb.load_index_id_701276 scheduled__2024-06-06T00:00:00+00:00 [queued]>
[2024-06-07T00:06:17.368+0000] {taskinstance.py:2073} INFO - Dependencies all met for dep_context=requeueable deps ti=<TaskInstance: load_data_mb.load_index_id_701276 scheduled__2024-06-06T00:00:00+00:00 [queued]>
[2024-06-07T00:06:17.369+0000] {taskinstance.py:2303} INFO - Starting attempt 1 of 1
[2024-06-07T00:06:17.390+0000] {taskinstance.py:2327} INFO - Executing <Task(PythonOperator): load_index_id_701276> on 2024-06-06 00:00:00+00:00
[2024-06-07T00:06:17.399+0000] {logging_mixin.py:188} WARNING - /home/***/.local/lib/python3.12/site-packages/***/task/task_runner/standard_task_runner.py:61 DeprecationWarning: This process (pid=4226) is multi-threaded, use of fork() may lead to deadlocks in the child.
[2024-06-07T00:06:17.401+0000] {standard_task_runner.py:63} INFO - Started process 4227 to run task
[2024-06-07T00:06:17.399+0000] {standard_task_runner.py:90} INFO - Running: ['***', 'tasks', 'run', 'load_data_mb', 'load_index_id_701276', 'scheduled__2024-06-06T00:00:00+00:00', '--job-id', '82', '--raw', '--subdir', 'DAGS_FOLDER/load_data_mb.py', '--cfg-path', '/tmp/tmpaojb0hzy']
[2024-06-07T00:06:17.402+0000] {standard_task_runner.py:91} INFO - Job 82: Subtask load_index_id_701276
[2024-06-07T00:06:17.460+0000] {task_command.py:426} INFO - Running <TaskInstance: load_data_mb.load_index_id_701276 scheduled__2024-06-06T00:00:00+00:00 [running]> on host e6f094d2943c
[2024-06-07T00:06:17.577+0000] {taskinstance.py:2644} INFO - Exporting env vars: AIRFLOW_CTX_DAG_OWNER='***' AIRFLOW_CTX_DAG_ID='load_data_mb' AIRFLOW_CTX_TASK_ID='load_index_id_701276' AIRFLOW_CTX_EXECUTION_DATE='2024-06-06T00:00:00+00:00' AIRFLOW_CTX_TRY_NUMBER='1' AIRFLOW_CTX_DAG_RUN_ID='scheduled__2024-06-06T00:00:00+00:00'
[2024-06-07T00:06:17.578+0000] {taskinstance.py:430} INFO - ::endgroup::
[2024-06-07T00:06:37.432+0000] {taskinstance.py:441} INFO - ::group::Post task execution logs
[2024-06-07T00:06:37.434+0000] {taskinstance.py:2890} ERROR - Task failed with exception
Traceback (most recent call last):
  File "/home/airflow/.local/lib/python3.12/site-packages/requests/models.py", line 971, in json
    return complexjson.loads(self.text, **kwargs)
           ^^^^^^^^^^^^^^^^^^^^^^^^^^^^^^^^^^^^^^
  File "/usr/local/lib/python3.12/json/__init__.py", line 346, in loads
    return _default_decoder.decode(s)
           ^^^^^^^^^^^^^^^^^^^^^^^^^^
  File "/usr/local/lib/python3.12/json/decoder.py", line 337, in decode
    obj, end = self.raw_decode(s, idx=_w(s, 0).end())
               ^^^^^^^^^^^^^^^^^^^^^^^^^^^^^^^^^^^^^^
  File "/usr/local/lib/python3.12/json/decoder.py", line 355, in raw_decode
    raise JSONDecodeError("Expecting value", s, err.value) from None
json.decoder.JSONDecodeError: Expecting value: line 2 column 1 (char 1)

During handling of the above exception, another exception occurred:

Traceback (most recent call last):
  File "/home/airflow/.local/lib/python3.12/site-packages/airflow/models/taskinstance.py", line 465, in _execute_task
    result = _execute_callable(context=context, **execute_callable_kwargs)
             ^^^^^^^^^^^^^^^^^^^^^^^^^^^^^^^^^^^^^^^^^^^^^^^^^^^^^^^^^^^^^
  File "/home/airflow/.local/lib/python3.12/site-packages/airflow/models/taskinstance.py", line 432, in _execute_callable
    return execute_callable(context=context, **execute_callable_kwargs)
           ^^^^^^^^^^^^^^^^^^^^^^^^^^^^^^^^^^^^^^^^^^^^^^^^^^^^^^^^^^^^
  File "/home/airflow/.local/lib/python3.12/site-packages/airflow/models/baseoperator.py", line 400, in wrapper
    return func(self, *args, **kwargs)
           ^^^^^^^^^^^^^^^^^^^^^^^^^^^
  File "/home/airflow/.local/lib/python3.12/site-packages/airflow/operators/python.py", line 235, in execute
    return_value = self.execute_callable()
                   ^^^^^^^^^^^^^^^^^^^^^^^
  File "/home/airflow/.local/lib/python3.12/site-packages/airflow/operators/python.py", line 252, in execute_callable
    return self.python_callable(*self.op_args, **self.op_kwargs)
           ^^^^^^^^^^^^^^^^^^^^^^^^^^^^^^^^^^^^^^^^^^^^^^^^^^^^^
  File "/opt/airflow/dags/load_data_mb.py", line 26, in load_index
    print(response.json())
          ^^^^^^^^^^^^^^^
  File "/home/airflow/.local/lib/python3.12/site-packages/requests/models.py", line 975, in json
    raise RequestsJSONDecodeError(e.msg, e.doc, e.pos)
requests.exceptions.JSONDecodeError: Expecting value: line 2 column 1 (char 1)
[2024-06-07T00:06:37.472+0000] {taskinstance.py:1205} INFO - Marking task as FAILED. dag_id=load_data_mb, task_id=load_index_id_701276, execution_date=20240606T000000, start_date=20240607T000617, end_date=20240607T000637
[2024-06-07T00:06:37.498+0000] {standard_task_runner.py:110} ERROR - Failed to execute job 82 for task load_index_id_701276 (Expecting value: line 2 column 1 (char 1); 4227)
[2024-06-07T00:06:37.512+0000] {local_task_job_runner.py:240} INFO - Task exited with return code 1
[2024-06-07T00:06:37.534+0000] {taskinstance.py:3482} INFO - 0 downstream tasks scheduled from follow-on schedule check
[2024-06-07T00:06:37.540+0000] {local_task_job_runner.py:222} INFO - ::endgroup::
